<mujoco>
  <option density="1.204" viscosity="1.8e-5" integrator="implicit"/>
  <option gravity="0 0 -9.81"/>
  <visual>
    <global elevation="-10"/>
  </visual>
  <default>
    <tendon limited="true" width="0.003" rgba="1 1 1 1"/>
    <geom friction=".2"/>
    <default class="weight">
      <geom rgba=".8 .4 .8 1"/>
      <site rgba=".8 .4 .8 1"/>
    </default>
    <default class="balloon">
      <!--
        0.167 is the MKS density of helium at room temperature.
        Note this does not take into account the mass of the rubber,
        which is likely not insignificant.
      -->
      <geom density="0.167" fluidshape="ellipsoid"/>
      <default class="pink">
        <geom rgba="1 .6 .7 1"/>
        <site rgba="1 .6 .7 1"/>
      </default>
      <default class="blue">
        <geom rgba=".3 .7 .9 1"/>
        <site rgba=".3 .7 .9 1"/>
      </default>
      <default class="green">
        <geom rgba=".4 .9 .5 1"/>
        <site rgba=".4 .9 .5 1"/>
      </default>
      <default class="orange">
        <geom rgba="1 .4 0 1"/>
        <site rgba="1 .4 0 1"/>
      </default>
    </default>
  </default>
  <asset>
    <texture name="grid" type="2d" builtin="checker" width="512" height="512" rgb2="0 0 0" rgb1="1 1 1"/>
    <material name="grid" texture="grid" texrepeat="2 2" texuniform="true" reflectance=".6"/>
  </asset>

  <worldbody>
    <geom name="ground" type="plane" size="5 5 .05" pos="0 0 -.5" material="grid"/>

    <!-- 本体（ベース） -->
    <body name="tb3_base" pos="0 0 0.05" childclass="orange">
      <freejoint/>
      <geom name="base" type="box" size="0.13 0.13 0.16" mass="1.0"/>
      
      <!-- 左車輪 -->
      <body name="left_wheel" pos="0.1 0.17 -0.12" euler="90 0 0" childclass="pink">
        <joint name="left_wheel_hinge" type="hinge" axis="0 0 -1" damping="0.1"/>
        <geom name="left_wheel_geom" type="cylinder" size="0.1 0.03" density="500" friction="1.1"/>
      </body>

      <!-- 右車輪 -->
      <body name="right_wheel" pos="0.1 -0.17 -0.12" euler="90 0 0" childclass="green">
        <joint name="right_wheel_hinge" type="hinge" axis="0 0 -1" damping="0.1"/>
        <geom name="right_wheel_geom" type="cylinder" size="0.1 0.03" density="500" friction="1.1"/>
      </body>

      <!-- キャスター -->
      <body name="back_castor" pos="-0.12 0 -0.175" childclass="blue">
        <joint name="castor_yaw" type="hinge" axis="0 0 1" damping="0.1"/>
        <joint name="castor_pitch" type="hinge" axis="0 1 0" damping="0.1"/>
        <joint name="castor_roll" type="hinge" axis="1 0 0" damping="0.1"/>
        <geom name="castor" type="sphere" size="0.02" density="500" friction="0.5"/>
      </body>
    </body>
  </worldbody>
  <actuator>
    <!-- 左モーター（初期値5.0で回転） -->
    <motor name="left_motor" joint="left_wheel_hinge" ctrllimited="true" ctrlrange="-10 10"  gear = "1.0"/>

    <!-- 右モーター（初期値5.0で回転） -->
    <motor name="right_motor" joint="right_wheel_hinge" ctrllimited="true" ctrlrange="-10 10"  gear = "1.0"/>
  </actuator>
</mujoco>
